<mujoco model="R5a_single_arm_grid">
  <compiler angle="radian" meshdir="./R5/R5a/meshes" autolimits="true"/>
  
  <option timestep="0.002" gravity="0 0 -9.81"/>

  <asset>
    <texture name="grid" type="2d" builtin="checker" width="512" height="512" rgb1=".1 .2 .3" rgb2=".2 .3 .4"/>
    <material name="grid" texture="grid" texrepeat="1 1" texuniform="true" reflectance=".2"/>
    
    <mesh name="base_link" file="base_link.STL"/>
    <mesh name="link1" file="link1.STL"/>
    <mesh name="link2" file="link2.STL"/>
    <mesh name="link3" file="link3.STL"/>
    <mesh name="link4" file="link4.STL"/>
    <mesh name="link5" file="link5.STL"/>
    <mesh name="link6" file="link6.STL"/>
    <mesh name="link7" file="link7.STL"/>
    <mesh name="link8" file="link8.STL"/>

    <material name="grey" rgba="0.56 0.56 0.56 1"/>
    <material name="light_grey" rgba="0.89 0.91 0.92 1"/>
    <material name="blue_grey" rgba="0.79 0.81 0.93 1"/>
  </asset>

  <worldbody>
    <light pos="0 0 1.5" dir="0 0 -1" directional="true"/>
    
    <geom name="floor" type="plane" size="5 5 0.1" material="grid"/>

    <body name="base_link" pos="0 0 0">
      <inertial pos="-0.00013359 6.672E-05 0.031672" mass="0.42272" fullinertia="0.00019 0.00019 0.00020 0 0 0"/>
      <geom type="mesh" mesh="base_link" material="light_grey"/>
      
      <body name="link1" pos="0 0 0.0565">
        <inertial pos="0.0050395 -0.0077407 0.020897" mass="0.096804" fullinertia="0.00011 0.00005 0.00010 -0.00001 0.00001 -0.00001"/>
        <joint name="joint1" axis="0 0 1" range="-10 10"/>
        <geom type="mesh" mesh="link1" material="grey"/>
        
        <body name="link2" pos="0.02 0 0.047">
          <inertial pos="-0.12992 -0.0011822 -2.6366E-05" mass="1.1988" fullinertia="0.00065 0.01647 0.01646 0.00008 0 0"/>
          <joint name="joint2" axis="0 1 0" range="-10 10"/>
          <geom type="mesh" mesh="link2" material="blue_grey"/>

          <body name="link3" pos="-0.264 0 0" euler="-3.1416 0 0">
            <inertial pos="0.16181 0.0011723 -0.05455" mass="0.84082" fullinertia="0.00082 0.00849 0.00834 0.00008 -0.00074 0.00001"/>
            <joint name="joint3" axis="0 1 0" range="-10 10"/>
            <geom type="mesh" mesh="link3" material="light_grey"/>
            
            <body name="link4" pos="0.245 -5E-05 -0.06">
                <inertial pos="0.041751 0.0054236 -0.03337" mass="0.12432" fullinertia="0.00022 0.00025 0.00017 -0.00002 -0.00009 0.00002"/>
                <joint name="joint4" axis="0 1 0" range="-10 10"/>
                <geom type="mesh" mesh="link4" material="blue_grey"/>

                <body name="link5" pos="0.073914 5E-05 -0.083391">
                    <inertial pos="-8.3435E-05 -1.5428E-05 0.052216" mass="0.63601" fullinertia="0.00084 0.00082 0.00026 0 0.00007 0"/>
                    <joint name="joint5" axis="0 0 1" range="-10 10"/>
                    <geom type="mesh" mesh="link5" material="grey"/>

                    <body name="link6" pos="0.025286 0 0.083391" euler="3.1416 0 0"> 
                        <inertial pos="0.041697 2.4368E-05 0.00014464" mass="0.44089" fullinertia="0.00038 0.00028 0.00050 0 0 0"/>
                        <joint name="joint6" axis="1 0 0" range="-10 10"/>
                        <site name="end_effector" pos="0.086 0 0" size="0.01" rgba="1 0 0 1"/>
                        <geom type="mesh" mesh="link6" material="light_grey"/>
                        
                        <body name="link7" pos="0.08657 0.024896 -0.0002436">
                            <inertial pos="-0.000355 -0.007827 -0.002988" mass="0.0648" diaginertia="2e-5 3e-5 3e-5"/>
                            <joint name="joint7" type="slide" axis="0 1 0" range="0 0.044"/>
                            <geom type="mesh" mesh="link7" material="light_grey"/>
                        </body>
                        
                        <body name="link8" pos="0.08657 -0.0249 -0.00024366">
                            <inertial pos="-0.000355 0.007827 0.00242" mass="0.0648" diaginertia="2e-5 3e-5 3e-5"/>
                            <joint name="joint8" type="slide" axis="0 -1 0" range="0 0.044"/>
                            <geom type="mesh" mesh="link8" material="light_grey"/>
                        </body>
                    </body>
                </body>
            </body>
          </body>
        </body>
      </body>
    </body>
  </worldbody>

  <actuator>
    <position name="act_j1" joint="joint1" kp="800" kv="50"/>
    <position name="act_j2" joint="joint2" kp="800" kv="50"/>
    <position name="act_j3" joint="joint3" kp="800" kv="50"/>
    <position name="act_j4" joint="joint4" kp="500" kv="30"/>
    <position name="act_j5" joint="joint5" kp="300" kv="20"/>
    <position name="act_j6" joint="joint6" kp="200" kv="10"/>
    
    <position name="act_j7" joint="joint7" kp="100" kv="5"/>
    <position name="act_j8" joint="joint8" kp="100" kv="5"/>
  </actuator>
</mujoco>